<?xml version="1.0" encoding="utf-8"?>
<mujoco model="base_cabinet_600_with_human">
  <compiler angle="radian" meshdir="assets" texturedir="assets" autolimits="true"/>

  <!-- Keep the same assets/defaults from base_cabinet_600.xml -->
    <asset>
        <texture type="2d" name="drawer_600_full" file="drawer_600_full.png"/>
        <texture type="2d" name="drawer_600_half" file="drawer_600_half.png"/>
        <texture type="2d" name="drawer_600_quarter" file="drawer_600_quarter.png"/>
        <texture type="2d" name="counter" file="counter.png"/>
        <texture type="2d" name="hob" file="hob.png"/>
        <texture type="2d" name="handle" file="handle.png"/>
        <material name="cabinet" shininess="0.1"/>
        <material name="back" shininess="0.1"/>
        <material name="counter" shininess="0.1" texture="counter" texuniform="true" texrepeat="2 2"/>
        <material name="hob" texture="hob"/>
        <material name="drawer_600_full" shininess="0.1" texture="drawer_600_full"/>
        <material name="drawer_600_half" shininess="0.1" texture="drawer_600_half"/>
        <material name="drawer_600_quarter" shininess="0.1" texture="drawer_600_quarter"/>
        <material name="handle" rgba="0.5 0.5 0.5 1" texture="handle"/>
        <mesh file="drawer_600_full.obj"/>
        <mesh file="drawer_600_half.obj"/>
        <mesh file="drawer_600_quarter.obj"/>
        <mesh file="drawer_handle.obj"/>
    </asset>

  <default>
    <default class="base_cabinet_600">
      <geom density="10" solimp="0.998 0.998 0.001" solref="0.004 1"/>
      <joint solimplimit="0.998 0.998 0.001" solreflimit="0.004 1"/>
      <default class="visual">
        <geom contype="0" conaffinity="0"/>
      </default>
      <default class="collision">
        <geom mass="0" group="3"/>
      </default>
      <site size="0.001" rgba="0.5 0.5 0.5 0.3" group="4"/>
    </default>
  </default>

  <worldbody>
    <!-- content from base_cabinet_600.xml -->
    <body name="base_cabinet_600" childclass="base_cabinet_600" pos="0.7 0 0">
      <body name="walls">
        <geom pos="0 -0.048 0.47" size="0.298 0.35 0.002" type="box" material="back" euler="1.5708 0 0"/>
        <geom pos="0.292 -0.3 0.47" size="0.25 0.35 0.008" type="box" material="cabinet" euler="1.5708 1.5708 0"/>
        <geom pos="-0.292 -0.3 0.47" size="0.25 0.35 0.008" type="box" material="cabinet" euler="1.5708 1.5708 0"/>
        <body name="shelf_bottom">
          <geom pos="0 -0.3 0.128" size="0.25 0.284 0.008" type="box" material="cabinet" euler="0 0 1.5708"/>
        </body>
        <geom pos="0 -0.51 0.812" size="0.04 0.284 0.008" type="box" material="cabinet" euler="0 0 1.5708"/>
        <geom pos="0 -0.298 0.06" size="0.3 0.06 0.248" type="box" material="cabinet" euler="1.5708 0 0"/>
      </body>
      <body name="counter" pos="0 -0.2985 0.84">
        <geom class="visual" size="0.298 0.298 0.019" type="box" material="counter" euler="0 0 1.5708"/>
        <geom class="visual" pos="0 -0.299 0" size="0.3 0.019 0.001" type="box" material="counter" euler="1.5708 0 0"/>
        <geom class="visual" pos="0 0.299 0" size="0.3 0.019 0.001" type="box" material="counter" euler="1.5708 0 0"/>
        <geom class="visual" pos="0.299 0 0" size="0.3 0.019 0.001" type="box" material="counter" euler="1.5708 1.5708 0"/>
        <geom class="visual" pos="-0.299 0 0" size="0.3 0.019 0.001" type="box" material="counter" euler="1.5708 1.5708 0"/>
        <geom class="collision" size="0.3 0.3 0.019" type="box" euler="0 0 1.5708" solimp="0.95 0.98 0.001"/>
      </body>
      <body name="hob" pos="0 -0.3 0.85">
        <geom size="0.29 0.257 0.02" type="box" material="hob" solimp="0.95 0.98 0.001"/>
        <site name="hob_site_1" pos="-0.155 -0.08 0.02"/>
        <site name="hob_site_2" pos="-0.155 0.142 0.02"/>
        <site name="hob_site_3" pos="0.122 0.122 0.02"/>
        <site name="hob_site_4" pos="0.168 -0.096 0.02"/>
      </body>
      <body name="shelf" pos="0 -0.2985 0.474">
        <geom size="0.25 0.284 0.008" type="box" material="cabinet" euler="0 0 1.5708"/>
      </body>
      <body name="panel" pos="0 -0.56 0.474">
        <geom pos="0 0 0" type="mesh" mesh="drawer_600_full" material="drawer_600_full" euler="1.5708 0 0"/>
      </body>
      <body name="door_right" pos="-0.29 -0.56 0.474">
        <joint pos="0 -0.008 0" name="door_right" type="hinge" axis="0 0 -1" damping="0.2" range="0 1.5708"/>
        <geom pos="0.29 -0.004 0" type="mesh" mesh="drawer_600_full" material="drawer_600_full" euler="1.5708 0 0"/>
        <body pos="0.56 0 0.2" euler="-3.1416 1.5708 0">
          <geom type="mesh" mesh="drawer_handle" material="handle" class="visual" euler="1.5708 0 0"/>
          <geom pos="0 0.027 0" size="0.06 0.0032 0.006" type="box" class="collision"/>
          <geom pos="-0.0425 0.015 0" size="0.006 0.015 0.006" type="box" class="collision"/>
          <geom pos="0.0425 0.015 0" size="0.006 0.015 0.006" type="box" class="collision"/>
        </body>
      </body>
      <body name="door_left" pos="0.29 -0.56 0.474">
        <joint pos="0 -0.008 0" name="door_left" type="hinge" axis="0 0 1" damping="0.2" range="0 1.5708"/>
        <geom pos="-0.29 -0.004 0" type="mesh" mesh="drawer_600_full" material="drawer_600_full" euler="1.5708 0 0"/>
        <body pos="-0.56 0 0.2" euler="-3.1416 1.5708 0">
          <geom type="mesh" mesh="drawer_handle" material="handle" class="visual" euler="1.5708 0 0"/>
          <geom pos="0 0.027 0" size="0.06 0.0032 0.006" type="box" class="collision"/>
          <geom pos="-0.0425 0.015 0" size="0.006 0.015 0.006" type="box" class="collision"/>
          <geom pos="0.0425 0.015 0" size="0.006 0.015 0.006" type="box" class="collision"/>
        </body>
      </body>
      <body name="drawer_big_1" pos="0 -0.325 0.148">
        <joint name="drawer_big_1" type="slide" axis="0 -1 0" damping="10" range="0 0.38" frictionloss="1"/>
        <geom pos="0 0 0" size="0.223 0.269 0.002" type="box" material="cabinet" euler="0 0 1.5708"/>
        <geom pos="-0.263 0 0.149" size="0.225 0.147 0.008" type="box" material="cabinet" euler="1.5708 1.5708 0"/>
        <geom pos="0.263 0 0.149" size="0.225 0.147 0.008" type="box" material="cabinet" euler="1.5708 1.5708 0"/>
        <geom pos="0 0.217 0.149" size="0.255 0.147 0.008" type="box" material="cabinet" euler="1.5708 0 0"/>
        <geom pos="0 -0.217 0.1475" size="0.255 0.147 0.008" type="box" material="cabinet" euler="1.5708 0 0"/>
        <geom pos="0 -0.236 0.1475" type="mesh" mesh="drawer_600_half" material="drawer_600_half" euler="1.5708 0 0"/>
        <body pos="0 -0.236 0.290" euler="-3.1416 0 0">
          <geom type="mesh" mesh="drawer_handle" material="handle" class="visual" euler="1.5708 0 0"/>
          <geom pos="0 0.027 0" size="0.06 0.0032 0.006" type="box" class="collision"/>
          <geom pos="-0.0425 0.015 0" size="0.006 0.015 0.006" type="box" class="collision"/>
          <geom pos="0.0425 0.015 0" size="0.006 0.015 0.006" type="box" class="collision"/>
        </body>
        <site name="drawer_big_1" pos="0 0 0.002"/>
      </body>
      <body name="drawer_big_2" pos="0 -0.325 0.495">
        <joint name="drawer_big_2" type="slide" axis="0 -1 0" damping="10" range="0 0.38" frictionloss="1"/>
        <geom pos="0 0 0" size="0.223 0.269 0.002" type="box" material="cabinet" euler="0 0 1.5708"/>
        <geom pos="-0.263 0 0.149" size="0.225 0.147 0.008" type="box" material="cabinet" euler="1.5708 1.5708 0"/>
        <geom pos="0.263 0 0.149" size="0.225 0.147 0.008" type="box" material="cabinet" euler="1.5708 1.5708 0"/>
        <geom pos="0 0.217 0.149" size="0.255 0.147 0.008" type="box" material="cabinet" euler="1.5708 0 0"/>
        <geom pos="0 -0.217 0.1475" size="0.255 0.147 0.008" type="box" material="cabinet" euler="1.5708 0 0"/>
        <geom pos="0 -0.236 0.1475" type="mesh" mesh="drawer_600_half" material="drawer_600_half" euler="1.5708 0 0"/>
        <body pos="0 -0.236 0.290" euler="-3.1416 0 0">
          <geom type="mesh" mesh="drawer_handle" material="handle" class="visual" euler="1.5708 0 0"/>
          <geom pos="0 0.027 0" size="0.06 0.0032 0.006" type="box" class="collision"/>
          <geom pos="-0.0425 0.015 0" size="0.006 0.015 0.006" type="box" class="collision"/>
          <geom pos="0.0425 0.015 0" size="0.006 0.015 0.006" type="box" class="collision"/>
        </body>
        <site name="drawer_big_2" pos="0 0 0.002"/>
      </body>
      <body name="drawer_small_1" pos="0 -0.325 0.148">
        <joint name="drawer_small_1" type="slide" axis="0 -1 0" damping="10" range="0 0.38" frictionloss="1"/>
        <geom pos="0 0 0" size="0.223 0.269 0.002" type="box" material="cabinet" euler="0 0 1.5708"/>
        <geom pos="-0.263 0 0.0605" size="0.225 0.059 0.008" type="box" material="cabinet" euler="1.5708 1.5708 0"/>
        <geom pos="0.263 0 0.0605" size="0.225 0.059 0.008" type="box" material="cabinet" euler="1.5708 1.5708 0"/>
        <geom pos="0 0.217 0.0605" size="0.255 0.059 0.008" type="box" material="cabinet" euler="1.5708 0 0"/>
        <geom pos="0 -0.217 0.0605" size="0.255 0.059 0.008" type="box" material="cabinet" euler="1.5708 0 0"/>
        <geom pos="0 -0.236 0.0623" type="mesh" mesh="drawer_600_quarter" material="drawer_600_quarter" euler="1.5708 0 0"/>
        <body pos="0 -0.236 0.0623" euler="-3.1416 0 0">
          <geom type="mesh" mesh="drawer_handle" material="handle" class="visual" euler="1.5708 0 0"/>
          <geom pos="0 0.027 0" size="0.06 0.0032 0.006" type="box" class="collision"/>
          <geom pos="-0.0425 0.015 0" size="0.006 0.015 0.006" type="box" class="collision"/>
          <geom pos="0.0425 0.015 0" size="0.006 0.015 0.006" type="box" class="collision"/>
        </body>
        <site name="drawer_small_1" pos="0 0 0.002"/>
      </body>
      <body name="drawer_small_2" pos="0 -0.325 0.32">
        <joint name="drawer_small_2" type="slide" axis="0 -1 0" damping="10" range="0 0.38" frictionloss="1"/>
        <geom pos="0 0 0" size="0.223 0.269 0.002" type="box" material="cabinet" euler="0 0 1.5708"/>
        <geom pos="-0.263 0 0.0605" size="0.225 0.059 0.008" type="box" material="cabinet" euler="1.5708 1.5708 0"/>
        <geom pos="0.263 0 0.0605" size="0.225 0.059 0.008" type="box" material="cabinet" euler="1.5708 1.5708 0"/>
        <geom pos="0 0.217 0.0605" size="0.255 0.059 0.008" type="box" material="cabinet" euler="1.5708 0 0"/>
        <geom pos="0 -0.217 0.0605" size="0.255 0.059 0.008" type="box" material="cabinet" euler="1.5708 0 0"/>
        <geom pos="0 -0.236 0.0623" type="mesh" mesh="drawer_600_quarter" material="drawer_600_quarter" euler="1.5708 0 0"/>
        <body pos="0 -0.236 0.0623" euler="-3.1416 0 0">
          <geom type="mesh" mesh="drawer_handle" material="handle" class="visual" euler="1.5708 0 0"/>
          <geom pos="0 0.027 0" size="0.06 0.0032 0.006" type="box" class="collision"/>
          <geom pos="-0.0425 0.015 0" size="0.006 0.015 0.006" type="box" class="collision"/>
          <geom pos="0.0425 0.015 0" size="0.006 0.015 0.006" type="box" class="collision"/>
        </body>
        <site name="drawer_small_2" pos="0 0 0.002"/>
      </body>
      <body name="drawer_small_3" pos="0 -0.325 0.492">
        <joint name="drawer_small_3" type="slide" axis="0 -1 0" damping="10" range="0 0.38" frictionloss="1"/>
        <geom pos="0 0 0" size="0.223 0.269 0.002" type="box" material="cabinet" euler="0 0 1.5708"/>
        <geom pos="-0.263 0 0.0605" size="0.225 0.059 0.008" type="box" material="cabinet" euler="1.5708 1.5708 0"/>
        <geom pos="0.263 0 0.0605" size="0.225 0.059 0.008" type="box" material="cabinet" euler="1.5708 1.5708 0"/>
        <geom pos="0 0.217 0.0605" size="0.255 0.059 0.008" type="box" material="cabinet" euler="1.5708 0 0"/>
        <geom pos="0 -0.217 0.0605" size="0.255 0.059 0.008" type="box" material="cabinet" euler="1.5708 0 0"/>
        <geom pos="0 -0.236 0.0623" type="mesh" mesh="drawer_600_quarter" material="drawer_600_quarter" euler="1.5708 0 0"/>
        <body pos="0 -0.236 0.0623" euler="-3.1416 0 0">
          <geom type="mesh" mesh="drawer_handle" material="handle" class="visual" euler="1.5708 0 0"/>
          <geom pos="0 0.027 0" size="0.06 0.0032 0.006" type="box" class="collision"/>
          <geom pos="-0.0425 0.015 0" size="0.006 0.015 0.006" type="box" class="collision"/>
          <geom pos="0.0425 0.015 0" size="0.006 0.015 0.006" type="box" class="collision"/>
        </body>
        <site name="drawer_small_3" pos="0 0 0.002"/>
      </body>
      <body name="drawer_small_4" pos="0 -0.325 0.664">
        <joint name="drawer_small_4" type="slide" axis="0 -1 0" damping="10" range="0 0.38" frictionloss="1"/>
        <geom pos="0 0 0" size="0.223 0.269 0.002" type="box" material="cabinet" euler="0 0 1.5708"/>
        <geom pos="-0.263 0 0.0605" size="0.225 0.059 0.008" type="box" material="cabinet" euler="1.5708 1.5708 0"/>
        <geom pos="0.263 0 0.0605" size="0.225 0.059 0.008" type="box" material="cabinet" euler="1.5708 1.5708 0"/>
        <geom pos="0 0.217 0.0605" size="0.255 0.059 0.008" type="box" material="cabinet" euler="1.5708 0 0"/>
        <geom pos="0 -0.217 0.0605" size="0.255 0.059 0.008" type="box" material="cabinet" euler="1.5708 0 0"/>
        <geom pos="0 -0.236 0.0623" type="mesh" mesh="drawer_600_quarter" material="drawer_600_quarter" euler="1.5708 0 0"/>
        <body pos="0 -0.236 0.0623" euler="-3.1416 0 0">
          <geom type="mesh" mesh="drawer_handle" material="handle" class="visual" euler="1.5708 0 0"/>
          <geom pos="0 0.027 0" size="0.06 0.0032 0.006" type="box" class="collision"/>
          <geom pos="-0.0425 0.015 0" size="0.006 0.015 0.006" type="box" class="collision"/>
          <geom pos="0.0425 0.015 0" size="0.006 0.015 0.006" type="box" class="collision"/>
        </body>
        <site name="drawer_small_4" pos="0 0 0.002"/>
      </body>
    </body>

      <body name="J0" mocap="true">
        <geom type="sphere" size="0.01" rgba="0.2 0.6 1 0.7" contype="0" conaffinity="0"/>
      </body>
      <body name="J1" mocap="true">
        <geom type="sphere" size="0.01" rgba="0.2 0.6 1 0.7" contype="0" conaffinity="0"/>
      </body>
      <body name="J2" mocap="true">
        <geom type="sphere" size="0.01" rgba="0.2 0.6 1 0.7" contype="0" conaffinity="0"/>
      </body>
      <body name="J3" mocap="true">
        <geom type="sphere" size="0.01" rgba="0.2 0.6 1 0.7" contype="0" conaffinity="0"/>
      </body>
      <body name="J4" mocap="true">
        <geom type="sphere" size="0.01" rgba="0.2 0.6 1 0.7" contype="0" conaffinity="0"/>
      </body>
      <body name="J5" mocap="true">
        <geom type="sphere" size="0.01" rgba="0.2 0.6 1 0.7" contype="0" conaffinity="0"/>
      </body>
      <body name="J6" mocap="true">
        <geom type="sphere" size="0.01" rgba="0.2 0.6 1 0.7" contype="0" conaffinity="0"/>
      </body>
      <body name="J7" mocap="true">
        <geom type="sphere" size="0.01" rgba="0.2 0.6 1 0.7" contype="0" conaffinity="0"/>
      </body>
      <body name="J8" mocap="true">
        <geom type="sphere" size="0.01" rgba="0.2 0.6 1 0.7" contype="0" conaffinity="0"/>
      </body>
      <body name="J9" mocap="true">
        <geom type="sphere" size="0.01" rgba="0.2 0.6 1 0.7" contype="0" conaffinity="0"/>
      </body>
      <body name="J10" mocap="true">
        <geom type="sphere" size="0.01" rgba="0.2 0.6 1 0.7" contype="0" conaffinity="0"/>
      </body>
      <body name="J11" mocap="true">
        <geom type="sphere" size="0.01" rgba="0.2 0.6 1 0.7" contype="0" conaffinity="0"/>
      </body>
      <body name="J12" mocap="true">
        <geom type="sphere" size="0.01" rgba="0.2 0.6 1 0.7" contype="0" conaffinity="0"/>
      </body>
      <body name="J13" mocap="true">
        <geom type="sphere" size="0.01" rgba="0.2 0.6 1 0.7" contype="0" conaffinity="0"/>
      </body>
      <body name="J14" mocap="true">
        <geom type="sphere" size="0.01" rgba="0.2 0.6 1 0.7" contype="0" conaffinity="0"/>
      </body>
      <body name="J15" mocap="true">
        <geom type="sphere" size="0.01" rgba="0.2 0.6 1 0.7" contype="0" conaffinity="0"/>
      </body>
      <body name="J16" mocap="true">
        <geom type="sphere" size="0.01" rgba="0.2 0.6 1 0.7" contype="0" conaffinity="0"/>
      </body>
      <body name="J17" mocap="true">
        <geom type="sphere" size="0.01" rgba="0.2 0.6 1 0.7" contype="0" conaffinity="0"/>
      </body>
      <body name="J18" mocap="true">
        <geom type="sphere" size="0.01" rgba="0.2 0.6 1 0.7" contype="0" conaffinity="0"/>
      </body>
      <body name="J19" mocap="true">
        <geom type="sphere" size="0.01" rgba="0.2 0.6 1 0.7" contype="0" conaffinity="0"/>
      </body>
      <body name="J20" mocap="true">
        <geom type="sphere" size="0.01" rgba="0.2 0.6 1 0.7" contype="0" conaffinity="0"/>
      </body>
      <body name="J21" mocap="true">
        <geom type="sphere" size="0.01" rgba="0.2 0.6 1 0.7" contype="0" conaffinity="0"/>
      </body>
      <body name="J22" mocap="true">
        <geom type="sphere" size="0.01" rgba="0.2 0.6 1 0.7" contype="0" conaffinity="0"/>
      </body>
      <body name="J23" mocap="true">
        <geom type="sphere" size="0.01" rgba="0.2 0.6 1 0.7" contype="0" conaffinity="0"/>
      </body>
      <body name="J24" mocap="true">
        <geom type="sphere" size="0.01" rgba="0.2 0.6 1 0.7" contype="0" conaffinity="0"/>
      </body>
      <body name="J25" mocap="true">
        <geom type="sphere" size="0.01" rgba="0.2 0.6 1 0.7" contype="0" conaffinity="0"/>
      </body>
      <body name="J26" mocap="true">
        <geom type="sphere" size="0.01" rgba="0.2 0.6 1 0.7" contype="0" conaffinity="0"/>
      </body>
      <body name="J27" mocap="true">
        <geom type="sphere" size="0.01" rgba="0.2 0.6 1 0.7" contype="0" conaffinity="0"/>
      </body>
      <body name="J28" mocap="true">
        <geom type="sphere" size="0.01" rgba="0.2 0.6 1 0.7" contype="0" conaffinity="0"/>
      </body>
      <body name="J29" mocap="true">
        <geom type="sphere" size="0.01" rgba="0.2 0.6 1 0.7" contype="0" conaffinity="0"/>
      </body>
      <body name="J30" mocap="true">
        <geom type="sphere" size="0.01" rgba="0.2 0.6 1 0.7" contype="0" conaffinity="0"/>
      </body>
      <body name="J31" mocap="true">
        <geom type="sphere" size="0.01" rgba="0.2 0.6 1 0.7" contype="0" conaffinity="0"/>
      </body>
      <body name="J32" mocap="true">
        <geom type="sphere" size="0.01" rgba="0.2 0.6 1 0.7" contype="0" conaffinity="0"/>
      </body>
      <body name="J33" mocap="true">
        <geom type="sphere" size="0.01" rgba="0.2 0.6 1 0.7" contype="0" conaffinity="0"/>
      </body>
      <body name="J34" mocap="true">
        <geom type="sphere" size="0.01" rgba="0.2 0.6 1 0.7" contype="0" conaffinity="0"/>
      </body>
      <body name="J35" mocap="true">
        <geom type="sphere" size="0.01" rgba="0.2 0.6 1 0.7" contype="0" conaffinity="0"/>
      </body>
      <body name="J36" mocap="true">
        <geom type="sphere" size="0.01" rgba="0.2 0.6 1 0.7" contype="0" conaffinity="0"/>
      </body>
      <body name="J37" mocap="true">
        <geom type="sphere" size="0.01" rgba="0.2 0.6 1 0.7" contype="0" conaffinity="0"/>
      </body>
      <body name="J38" mocap="true">
        <geom type="sphere" size="0.01" rgba="0.2 0.6 1 0.7" contype="0" conaffinity="0"/>
      </body>
      <body name="J39" mocap="true">
        <geom type="sphere" size="0.01" rgba="0.2 0.6 1 0.7" contype="0" conaffinity="0"/>
      </body>
      <body name="J40" mocap="true">
        <geom type="sphere" size="0.01" rgba="0.2 0.6 1 0.7" contype="0" conaffinity="0"/>
      </body>
      <body name="J41" mocap="true">
        <geom type="sphere" size="0.01" rgba="0.2 0.6 1 0.7" contype="0" conaffinity="0"/>
      </body>
      <body name="J42" mocap="true">
        <geom type="sphere" size="0.01" rgba="0.2 0.6 1 0.7" contype="0" conaffinity="0"/>
      </body>
      <body name="J43" mocap="true">
        <geom type="sphere" size="0.01" rgba="0.2 0.6 1 0.7" contype="0" conaffinity="0"/>
      </body>
      <body name="J44" mocap="true">
        <geom type="sphere" size="0.01" rgba="0.2 0.6 1 0.7" contype="0" conaffinity="0"/>
      </body>
      <body name="J45" mocap="true">
        <geom type="sphere" size="0.01" rgba="0.2 0.6 1 0.7" contype="0" conaffinity="0"/>
      </body>
      <body name="J46" mocap="true">
        <geom type="sphere" size="0.01" rgba="0.2 0.6 1 0.7" contype="0" conaffinity="0"/>
      </body>
      <body name="J47" mocap="true">
        <geom type="sphere" size="0.01" rgba="0.2 0.6 1 0.7" contype="0" conaffinity="0"/>
      </body>
      <body name="J48" mocap="true">
        <geom type="sphere" size="0.01" rgba="0.2 0.6 1 0.7" contype="0" conaffinity="0"/>
      </body>
      <body name="J49" mocap="true">
        <geom type="sphere" size="0.01" rgba="0.2 0.6 1 0.7" contype="0" conaffinity="0"/>
      </body>
      <body name="J50" mocap="true">
        <geom type="sphere" size="0.01" rgba="0.2 0.6 1 0.7" contype="0" conaffinity="0"/>
      </body>
      <body name="J51" mocap="true">
        <geom type="sphere" size="0.01" rgba="0.2 0.6 1 0.7" contype="0" conaffinity="0"/>
      </body>
      <body name="J52" mocap="true">
        <geom type="sphere" size="0.01" rgba="0.2 0.6 1 0.7" contype="0" conaffinity="0"/>
      </body>
      <body name="J53" mocap="true">
        <geom type="sphere" size="0.01" rgba="0.2 0.6 1 0.7" contype="0" conaffinity="0"/>
      </body>
      <body name="J54" mocap="true">
        <geom type="sphere" size="0.01" rgba="0.2 0.6 1 0.7" contype="0" conaffinity="0"/>
      </body>
      <body name="B0" mocap="true">
        <geom name="bone0" type="capsule" size="0.035000 0.054762" contype="2" conaffinity="1" rgba="1 0.6 0.6 0.6"/>
      </body>
      <body name="B1" mocap="true">
        <geom name="bone1" type="capsule" size="0.035000 0.059721" contype="2" conaffinity="1" rgba="1 0.6 0.6 0.6"/>
      </body>
      <body name="B2" mocap="true">
        <geom name="bone2" type="capsule" size="0.035000 0.056054" contype="2" conaffinity="1" rgba="1 0.6 0.6 0.6"/>
      </body>
      <body name="B3" mocap="true">
        <geom name="bone3" type="capsule" size="0.035000 0.196672" contype="2" conaffinity="1" rgba="1 0.6 0.6 0.6"/>
      </body>
      <body name="B4" mocap="true">
        <geom name="bone4" type="capsule" size="0.035000 0.189693" contype="2" conaffinity="1" rgba="1 0.6 0.6 0.6"/>
      </body>
      <body name="B5" mocap="true">
        <geom name="bone5" type="capsule" size="0.035000 0.082410" contype="2" conaffinity="1" rgba="1 0.6 0.6 0.6"/>
      </body>
      <body name="B6" mocap="true">
        <geom name="bone6" type="capsule" size="0.035000 0.204836" contype="2" conaffinity="1" rgba="1 0.6 0.6 0.6"/>
      </body>
      <body name="B7" mocap="true">
        <geom name="bone7" type="capsule" size="0.035000 0.207934" contype="2" conaffinity="1" rgba="1 0.6 0.6 0.6"/>
      </body>
      <body name="B8" mocap="true">
        <geom name="bone8" type="capsule" size="0.035000 0.031222" contype="2" conaffinity="1" rgba="1 0.6 0.6 0.6"/>
      </body>
      <body name="B9" mocap="true">
        <geom name="bone9" type="capsule" size="0.035000 0.076836" contype="2" conaffinity="1" rgba="1 0.6 0.6 0.6"/>
      </body>
      <body name="B10" mocap="true">
        <geom name="bone10" type="capsule" size="0.035000 0.077804" contype="2" conaffinity="1" rgba="1 0.6 0.6 0.6"/>
      </body>
      <body name="B11" mocap="true">
        <geom name="bone11" type="capsule" size="0.035000 0.081407" contype="2" conaffinity="1" rgba="1 0.6 0.6 0.6"/>
      </body>
      <body name="B12" mocap="true">
        <geom name="bone12" type="capsule" size="0.035000 0.043647" contype="2" conaffinity="1" rgba="1 0.6 0.6 0.6"/>
      </body>
      <body name="B13" mocap="true">
        <geom name="bone13" type="capsule" size="0.035000 0.042843" contype="2" conaffinity="1" rgba="1 0.6 0.6 0.6"/>
      </body>
      <body name="B14" mocap="true">
        <geom name="bone14" type="capsule" size="0.035000 0.084419" contype="2" conaffinity="1" rgba="1 0.6 0.6 0.6"/>
      </body>
      <body name="B15" mocap="true">
        <geom name="bone15" type="capsule" size="0.035000 0.073494" contype="2" conaffinity="1" rgba="1 0.6 0.6 0.6"/>
      </body>
      <body name="B16" mocap="true">
        <geom name="bone16" type="capsule" size="0.035000 0.066668" contype="2" conaffinity="1" rgba="1 0.6 0.6 0.6"/>
      </body>
      <body name="B17" mocap="true">
        <geom name="bone17" type="capsule" size="0.035000 0.130816" contype="2" conaffinity="1" rgba="1 0.6 0.6 0.6"/>
      </body>
      <body name="B18" mocap="true">
        <geom name="bone18" type="capsule" size="0.035000 0.136600" contype="2" conaffinity="1" rgba="1 0.6 0.6 0.6"/>
      </body>
      <body name="B19" mocap="true">
        <geom name="bone19" type="capsule" size="0.035000 0.131932" contype="2" conaffinity="1" rgba="1 0.6 0.6 0.6"/>
      </body>
      <body name="B20" mocap="true">
        <geom name="bone20" type="capsule" size="0.035000 0.127718" contype="2" conaffinity="1" rgba="1 0.6 0.6 0.6"/>
      </body>
      <body name="B21" mocap="true">
        <geom name="bone21" type="capsule" size="0.035000 0.009637" contype="2" conaffinity="1" rgba="1 0.6 0.6 0.6"/>
      </body>
      <body name="B22" mocap="true">
        <geom name="bone22" type="capsule" size="0.035000 0.037315" contype="2" conaffinity="1" rgba="1 0.6 0.6 0.6"/>
      </body>
      <body name="B23" mocap="true">
        <geom name="bone23" type="capsule" size="0.035000 0.042122" contype="2" conaffinity="1" rgba="1 0.6 0.6 0.6"/>
      </body>
      <body name="B24" mocap="true">
        <geom name="bone24" type="capsule" size="0.035000 0.052711" contype="2" conaffinity="1" rgba="1 0.6 0.6 0.6"/>
      </body>
      <body name="B25" mocap="true">
        <geom name="bone25" type="capsule" size="0.035000 0.016511" contype="2" conaffinity="1" rgba="1 0.6 0.6 0.6"/>
      </body>
      <body name="B26" mocap="true">
        <geom name="bone26" type="capsule" size="0.035000 0.011694" contype="2" conaffinity="1" rgba="1 0.6 0.6 0.6"/>
      </body>
      <body name="B27" mocap="true">
        <geom name="bone27" type="capsule" size="0.035000 0.056226" contype="2" conaffinity="1" rgba="1 0.6 0.6 0.6"/>
      </body>
      <body name="B28" mocap="true">
        <geom name="bone28" type="capsule" size="0.035000 0.015899" contype="2" conaffinity="1" rgba="1 0.6 0.6 0.6"/>
      </body>
      <body name="B29" mocap="true">
        <geom name="bone29" type="capsule" size="0.035000 0.012256" contype="2" conaffinity="1" rgba="1 0.6 0.6 0.6"/>
      </body>
      <body name="B30" mocap="true">
        <geom name="bone30" type="capsule" size="0.035000 0.049785" contype="2" conaffinity="1" rgba="1 0.6 0.6 0.6"/>
      </body>
      <body name="B31" mocap="true">
        <geom name="bone31" type="capsule" size="0.035000 0.010143" contype="2" conaffinity="1" rgba="1 0.6 0.6 0.6"/>
      </body>
      <body name="B32" mocap="true">
        <geom name="bone32" type="capsule" size="0.035000 0.009933" contype="2" conaffinity="1" rgba="1 0.6 0.6 0.6"/>
      </body>
      <body name="B33" mocap="true">
        <geom name="bone33" type="capsule" size="0.035000 0.052607" contype="2" conaffinity="1" rgba="1 0.6 0.6 0.6"/>
      </body>
      <body name="B34" mocap="true">
        <geom name="bone34" type="capsule" size="0.035000 0.014805" contype="2" conaffinity="1" rgba="1 0.6 0.6 0.6"/>
      </body>
      <body name="B35" mocap="true">
        <geom name="bone35" type="capsule" size="0.035000 0.012521" contype="2" conaffinity="1" rgba="1 0.6 0.6 0.6"/>
      </body>
      <body name="B36" mocap="true">
        <geom name="bone36" type="capsule" size="0.035000 0.025629" contype="2" conaffinity="1" rgba="1 0.6 0.6 0.6"/>
      </body>
      <body name="B37" mocap="true">
        <geom name="bone37" type="capsule" size="0.035000 0.015647" contype="2" conaffinity="1" rgba="1 0.6 0.6 0.6"/>
      </body>
      <body name="B38" mocap="true">
        <geom name="bone38" type="capsule" size="0.035000 0.013725" contype="2" conaffinity="1" rgba="1 0.6 0.6 0.6"/>
      </body>
      <body name="B39" mocap="true">
        <geom name="bone39" type="capsule" size="0.035000 0.052131" contype="2" conaffinity="1" rgba="1 0.6 0.6 0.6"/>
      </body>
      <body name="B40" mocap="true">
        <geom name="bone40" type="capsule" size="0.035000 0.016721" contype="2" conaffinity="1" rgba="1 0.6 0.6 0.6"/>
      </body>
      <body name="B41" mocap="true">
        <geom name="bone41" type="capsule" size="0.035000 0.011722" contype="2" conaffinity="1" rgba="1 0.6 0.6 0.6"/>
      </body>
      <body name="B42" mocap="true">
        <geom name="bone42" type="capsule" size="0.035000 0.055564" contype="2" conaffinity="1" rgba="1 0.6 0.6 0.6"/>
      </body>
      <body name="B43" mocap="true">
        <geom name="bone43" type="capsule" size="0.035000 0.015902" contype="2" conaffinity="1" rgba="1 0.6 0.6 0.6"/>
      </body>
      <body name="B44" mocap="true">
        <geom name="bone44" type="capsule" size="0.035000 0.012370" contype="2" conaffinity="1" rgba="1 0.6 0.6 0.6"/>
      </body>
      <body name="B45" mocap="true">
        <geom name="bone45" type="capsule" size="0.035000 0.049784" contype="2" conaffinity="1" rgba="1 0.6 0.6 0.6"/>
      </body>
      <body name="B46" mocap="true">
        <geom name="bone46" type="capsule" size="0.035000 0.010187" contype="2" conaffinity="1" rgba="1 0.6 0.6 0.6"/>
      </body>
      <body name="B47" mocap="true">
        <geom name="bone47" type="capsule" size="0.035000 0.010006" contype="2" conaffinity="1" rgba="1 0.6 0.6 0.6"/>
      </body>
      <body name="B48" mocap="true">
        <geom name="bone48" type="capsule" size="0.035000 0.052245" contype="2" conaffinity="1" rgba="1 0.6 0.6 0.6"/>
      </body>
      <body name="B49" mocap="true">
        <geom name="bone49" type="capsule" size="0.035000 0.014680" contype="2" conaffinity="1" rgba="1 0.6 0.6 0.6"/>
      </body>
      <body name="B50" mocap="true">
        <geom name="bone50" type="capsule" size="0.035000 0.012395" contype="2" conaffinity="1" rgba="1 0.6 0.6 0.6"/>
      </body>
      <body name="B51" mocap="true">
        <geom name="bone51" type="capsule" size="0.035000 0.025929" contype="2" conaffinity="1" rgba="1 0.6 0.6 0.6"/>
      </body>
      <body name="B52" mocap="true">
        <geom name="bone52" type="capsule" size="0.035000 0.015621" contype="2" conaffinity="1" rgba="1 0.6 0.6 0.6"/>
      </body>
      <body name="B53" mocap="true">
        <geom name="bone53" type="capsule" size="0.035000 0.013594" contype="2" conaffinity="1" rgba="1 0.6 0.6 0.6"/>
      </body>
  </worldbody>
</mujoco>
